Workbook

Sheet Instructions
A1: SMART EYE CAMERA vs SLIT LAMP — RESEARCH TEMPLATE (Excel)
B3: What this workbook is
B4: This is an Excel version of the Smart Eye Camera vs Slit Lamp research dashboard (originally built in R Shiny). It has the same patient entry, dataset, and analysis logic, organized across the tabs below.
B6: Tabs in this workbook
B7: Entry Form
B8: Fill in one patient at a time, then copy the assembled row into 'Patient Data'.
B9: Patient Data
B10: The master table of every patient — one row per patient, 51 columns. Pre-filled with 120 example (synthetic/fake) patients so every chart and test below already has something to show. Delete these example rows whenever you're ready to start your real study — everything recalculates automatically.
B11: Dashboard
B12: KPIs and charts: total patients, mean age, satisfaction %, gender, age, and diagnosis distributions.
B13: Clinical Analysis
B14: Slit Lamp vs Smart Camera comparison for IOP, SPH, CYL and Axis, with a paired t-test.
B15: Technical Comparison
... B33: - Dropdown lists (Gender, Examination Outcome, Convenience, etc.) are already set up on both the Entry Form and the Patient Data sheet, so typos are avoided. - Excel has no built-in Wilcoxon signed-rank test or Bland-Altman plot — see the note on the 'Statistical Tests' tab if you need those. - All numbers you see (KPIs, tables, chart data) are live formulas, not fixed numbers — editing or adding patient rows updates everything automatically.

Sheet Entry Form
A1: SMART EYE CAMERA vs SLIT LAMP — PATIENT ENTRY FORM
A2: Fill the yellow cells below for ONE patient. When done, scroll to the bottom row labelled 'COPY THIS ROW', select it, copy (Ctrl+C), go to the 'Patient Data' sheet, click the first empty row in column A, and Paste Special → Values (Ctrl+Alt+V, then V). Then come back here and clear the yellow cells for the next patient.
B5: 1. Demographics
B6: Study ID * | E6: Must be unique, e.g. EYE-121
B7: Patient Name
B8: Age
B9: Gender
B10: Address
B11: Date Entered | C11: =TODAY() -> 46275
B13: 2. Distance Vision & Refraction
C14: Slit Lamp | D14: Smart Camera
B15: VA (Visual Acuity) | E15: e.g. 6/6, 6/12, CF 1m
B16: PH (Pinhole) | E16: e.g. 6/9, NI, Not done
B17: BVCA (Best Corrected)
B18: IOP | E18: mmHg, numeric
B19: SPH | E19: diopters, e.g. -1.25
B20: CYL | E20: diopters, e.g. -0.50
B21: Axis | E21: 0-180
B23: 3. Clinical Examination
B24: Auto Refraction (R)
B25: Near Vision | E25: e.g. N6, N8, N10
B26: Extra Ocular Movement | E26: e.g. Full and free, Restricted
B27: Convergence | E27: e.g. Normal, Reduced, Absent
B28: Cover / Uncover Test | E28: e.g. Orthophoria, Esotropia
B29: Hirschberg - Straight | E29: e.g. Central, Not central
B30: Hirschberg - Deviation | E30: e.g. None, ~15° esotropia
B32: 4. Diagnosis & Treatment
B33: Diagnosis
B34: Treatment
B36: 5. Examination Outcome
C37: Slit Lamp | D37: Smart Camera
B38: Examination Result
B40: 6. Technical / Usability Comparison
C41: Slit Lamp | D41: Smart Camera
B42: 1. Convenience / Ease
B43: 2. Accuracy & Clarity
B44: 3. Time Efficiency
B45: 4. Training & Learning Curve
B46: 5. External Light Source
B47: 6. Portability
...

Sheet Patient Data
A1: Study_ID | B1: Patient_Name | C1: Age | D1: Gender | E1: Address | F1: Date_Entered | G1: VA_Slit | H1: PH_Slit | I1: BVCA_Slit | J1: VA_Camera | K1: PH_Camera | L1: BVCA_Camera | M1: IOP_Slit | N1: IOP_Camera | O1: SPH_Slit | P1: CYL_Slit | Q1: Axis_Slit | R1: SPH_Camera | S1: CYL_Camera | T1: Axis_Camera | U1: Auto_Refraction_Right | V1: Near_Vision | W1: Extra_Ocular_Movement | X1: Convergence | Y1: Cover_Uncover_Test | Z1: Hirschberg_Straight | AA1: Hirschberg_Deviation | AB1: Diagnosis | AC1: Treatment | AD1: Slit_Examination | AE1: Camera_Examination | AF1: Slit_Convenience | AG1: Camera_Convenience | AH1: Slit_Accuracy | AI1: Camera_Accuracy | AJ1: Slit_Time_Efficiency | AK1: Camera_Time_Efficiency | AL1: Slit_Training | AM1: Camera_Training | AN1: Slit_External_Light | AO1: Camera_External_Light | AP1: Slit_Portability | AQ1: Camera_Portability | AR1: Slit_Recording | AS1: Camera_Recording | AT1: Slit_Clinical_Examination | AU1: Camera_Clinical_Examination | AV1: Slit_Resolution | AW1: Camera_Resolution | AX1: Slit_Field_of_View | AY1: Camera_Field_of_View
A2: EYE-001 | B2: Ayesha Hussain | C2: 46 | D2: Female | E2: Saddar, Karachi | F2: 2024-09-07 | G2: 6/6 | H2: 6/18 | I2: 6/18 | J2: 6/6 | K2: 6/12 | L2: 6/6 | M2: 15.1 | N2: 16 | O2: 3.21 | P2: -1.11 | Q2: 30 | R2: 3.13 | S2: -0.72 | T2: 34 | U2: +3.13 / -0.72 x 34 | V2: N10 | W2: Full and free | X2: Reduced | Y2: Exophoria | Z2: Central, symmetric | AB2: Allergic Conjunctivitis | AC2: Spectacle correction reviewed and updated | AD2: Satisfactory | AE2: Not recorded | AF2: Easy | AG2: Easy | AH2: Satisfied | AI2: Satisfied | AJ2: No | AK2: Yes | AL2: Yes | AM2: No | AN2: Yes | AO2: No | AP2: Yes | AQ2: Yes | AR2: Yes | AS2: Yes | AT2: Yes | AU2: Yes | AV2: Yes | AW2: No | AX2: Yes | AY2: No
A3: EYE-002 | B3: Zainab Raza | C3: 29 | D3: Female | E3: Landhi, Karachi | F3: 2024-06-16 | G3: 6/12 | H3: 6/12 | I3: 6/24 | J3: HM | K3: 6/12 | L3: 6/60 | M3: 17.2 | N3: 16.6 | O3: -1.96 | P3: -2.62 | Q3: 90 | R3: -1.88 | S3: -3.05 | T3: 86 | U3: -1.88 / -3.05 x 86 | V3: N6 | W3: Full and free | X3: Normal | Y3: Orthophoria | Z3: Slightly nasal | AA3: ~15° esotropia | AB3: Corneal Opacity | AC3: No treatment required at this visit | AD3: Satisfactory | AE3: Not recorded | AF3: Difficult | AG3: Very Easy | AH3: Unsatisfied | AI3: Satisfied | AJ3: Yes | AK3: Yes | AL3: Yes | AM3: Yes | AN3: Yes | AO3: No | AP3: No | AQ3: Yes | AR3: Yes | AS3: Yes | AT3: Yes | AU3: Yes | AV3: Yes | AW3: Yes | AX3: No | AY3: No
A4: EYE-003 | B4: Yusra Baig | C4: 19 | D4: Female | E4: North Nazimabad, Karachi | F4: 2024-11-01 | G4: 6/18 | H4: 6/6 | I4: 6/18 | J4: 6/18 | K4: NI | L4: 6/36 | M4: 16.5 | N4: 15.2 | O4: -4.42 | P4: -1.1 | Q4: 170 | R4: -3.91 | S4: -1.08 | T4: 161 | U4: -3.91 / -1.08 x 161 | V4: N36 | W4: Full and free | X4: Normal | Y4: Orthophoria | Z4: Central | AB4: Normal Examination | AC4: Follow-up after 3 months advised | AD4: Not recorded | AE4: Satisfactory | AF4: Very Easy | AG4: Very Easy | AH4: Unsatisfied | AI4: Satisfied | AJ4: No | AK4: Yes | AL4: Yes | AM4: No | AN4: Yes | AO4: No | AP4: No | AQ4: Yes | AR4: No | AS4: No | AT4: Yes | AU4: Yes | AV4: Yes | AW4: Yes | AX4: Yes | AY4: Yes
A5: EYE-004 | B5: Amina Zaidi | C5: 28 | D5: Female | E5: Liaquatabad, Karachi | F5: 2025-04-29 | G5: 6/36 | H5: 6/6 | I5: 6/12 | J5: 6/36 | K5: 6/6 | L5: 6/12 | M5: 15.9 | N5: 14.3 | O5: 0.23 | P5: -1.16 | Q5: 30 | R5: 0.02 | S5: -1.31 | T5: 41 | U5: +0.02 / -1.31 x 41 | V5: N8 | W5: Restricted | X5: Normal | Y5: Orthophoria | Z5: Central, symmetric | AB5: Corneal Opacity | AC5: Patching therapy advised for amblyopia | AD5: Satisfactory | AE5: Satisfactory | AF5: Easy | AG5: Difficult | AH5: Satisfied | AI5: Unsatisfied | AJ5: Yes | AK5: Yes | AL5: Yes | AM5: Yes | AN5: Yes | AO5: No | AP5: No | AQ5: Yes | AR5: No | AS5: Yes | AT5: Yes | AU5: Yes | AV5: Yes | AW5: No | AX5: Yes | AY5: Yes
A6: EYE-005 | B6: Yusra Iqbal | C6: 37 | D6: Female | E6: Korangi, Karachi | F6: 2024-06-10 | G6: CF 2m | H6: 6/6 | I6: 6/24 | J6: 6/6 | K6: 6/12 | L6: 6/9 | M6: 12.1 | N6: 13.3 | O6: -3.92 | P6: -2.66 | Q6: 0 | R6: -3.85 | S6: -2.99 | T6: 1 | U6: -3.85 / -2.99 x 1 | V6: N10 | W6: Full and free | X6: Normal | Y6: Esophoria | Z6: Central, symmetric | AB6: Strabismus | AC6: Anti-glaucoma eye drops started | AD6: Not recorded | AE6: Satisfactory | AF6: Very Easy | AG6: Easy | AH6: Satisfied | AI6: Satisfied | AJ6: Yes | AK6: Yes | AL6: No | AM6: Yes | AN6: Yes | AO6: No | AP6: Yes | AQ6: Yes | AR6: No | AS6: Yes | AT6: Yes | AU6: Yes | AV6: Yes | AW6: Not recorded | AX6: Yes | AY6: No
A7: EYE-006 | B7: Javeria Hussain | C7: 51 | D7: Female | E7: Defence (DHA), Karachi | F7: 2025-06-01 | G7: 6/9 | H7: 6/6 | I7: 6/36 | J7: CF 1m | K7: 6/12 | L7: 6/6 | M7: 16 | N7: 15.8 | O7: -1.53 | P7: -1.55 | Q7: 90 | R7: -2.05 | S7: -1.67 | T7: 96 | U7: -2.05 / -1.67 x 96 | V7: N10 | W7: Full and free | X7: Reduced | Y7: Orthophoria | Z7: Central, symmetric | AB7: Refractive Error | AC7: Referred to retina specialist | AD7: Satisfactory | AE7: Satisfactory | AF7: Difficult | AG7: Very Easy | AH7: Satisfied | AI7: Satisfied | AJ7: No | AK7: Yes | AL7: No | AM7: Yes | AN7: No | AO7: Yes | AP7: No | AQ7: Yes | AR7: No | AS7: Yes | AT7: Yes | AU7: No | AV7: Yes | AW7: No | AX7: Yes | AY7: No
A8: EYE-007 | B8: Uzma Chaudhry | C8: 44 | D8: Female | E8: Liaquatabad, Karachi | F8: 2024-11-08 | G8: 6/36 | H8: 6/6 | I8: 6/9 | J8: 6/9 | K8: 6/6 | L8: 6/60 | M8: 9.9 | N8: 10.4 | O8: -1.75 | P8: -0.35 | Q8: 170 | R8: -1.99 | S8: -0.09 | T8: 175 | U8: -1.99 / -0.09 x 175 | V8: N18 | W8: Full and free | X8: Normal | Y8: Not recorded | Z8: Not central | AA8: ~20° exotropia | AB8: Allergic Conjunctivitis | AC8: No treatment required at this visit | AD8: Satisfactory | AE8: Not recorded | AF8: Easy | AG8: Very Easy | AH8: Satisfied | AI8: Satisfied | AJ8: Yes | AK8: Yes | AL8: No | AM8: Yes | AN8: Yes | AO8: No | AP8: No | AQ8: Not recorded | AR8: No | AS8: Yes | AT8: Yes | AU8: Yes | AV8: Yes | AW8: No | AX8: Yes | AY8: Yes
A9: EYE-008 | B9: Sana Anwar | C9: 22 | D9: Female | E9: Bahadurabad, Karachi | F9: 2024-01-01 | G9: 6/9 | H9: 6/12 | I9: 6/12 | J9: 6/12 | K9: 6/12 | L9: 6/12 | M9: 14.5 | N9: 15 | O9: 1.79 | P9: -1.07 | Q9: 45 | R9: 1.62 | S9: -1.35 | T9: 37 | U9: +1.62 / -1.35 x 37 | V9: N18 | W9: Normal | X9: Not recorded | Y9: Exotropia | Z9: Central, symmetric | AB9: Amblyopia | AC9: No treatment required at this visit | AD9: Not recorded | AE9: Unsatisfactory | AF9: Difficult | AG9: Easy | AH9: Satisfied | AI9: Satisfied | AJ9: No | AK9: Yes | AL9: Yes | AM9: Not recorded | AN9: Yes | AO9: Yes | AP9: No | AQ9: Yes | AR9: No | AS9: Yes | AT9: Yes | AU9: Yes | AV9: No | AW9: Yes | AX9: No | AY9: No
A10: EYE-009 | B10: Zainab Memon | C10: 52 | D10: Female | E10: Saddar, Karachi | F10: 2024-06-11 | G10: 6/60 | H10: NI | I10: 6/9 | J10: 6/12 | K10: NI | L10: 6/36 | M10: 19.8 | N10: 19.7 | O10: 1.86 | P10: -1.48 | Q10: 150 | R10: 1.99 | S10: -1.39 | T10: 159 | U10: +1.99 / -1.39 x 159 | V10: N36 | W10: Full and free | X10: Normal | Y10: Esophoria | Z10: Central, symmetric | AB10: Refractive Error | AC10: Lubricating eye drops prescribed | AD10: Not recorded | AE10: Not recorded | AF10: Easy | AG10: Easy | AH10: Satisfied | AI10: Satisfied | AJ10: Yes | AK10: Yes | AL10: Yes | AM10: Yes | AN10: Yes | AO10: No | AP10: Not recorded | AQ10: Yes | AR10: No | AS10: Yes | AT10: Yes | AU10: No | AV10: No | AW10: Yes | AX10: Yes | AY10: No
A11: EYE-010 | B11: Erum Soomro | C11: 37 | D11: Female | E11: Malir, Karachi | F11: 2024-05-18 | G11: 6/12 | H11: 6/9 | I11: 6/9 | J11: 6/6 | K11: 6/6 | L11: 6/36 | M11: 20.5 | N11: 16.8 | O11: 1.39 | P11: -1.17 | Q11: 170 | R11: 1.42 | S11: -1.15 | T11: 158 | U11: +1.42 / -1.15 x 158 | V11: N24 | W11: Normal | X11: Absent | Y11: Esophoria | Z11: Central, symmetric | AB11: Cataract | AC11: Surgical excision advised for pterygium | AD11: Satisfactory | AE11: Unsatisfactory | AF11: Difficult | AG11: Very Easy | AH11: Satisfied | AI11: Unsatisfied | AJ11: No | AK11: Yes | AL11: No | AM11: Yes | AN11: Yes | AO11: No | AP11: No | AQ11: Yes | AR11: No | AS11: Yes | AT11: Yes | AU11: Not recorded | AV11: Yes | AW11: Yes | AX11: Yes | AY11: Yes
A12: EYE-011 | B12: Hafsa Chaudhry | C12: 34 | D12: Female | E12: Gulshan-e-Iqbal, Karachi | F12: 2024-03-11 | G12: 6/24 | H12: 6/9 | I12: 6/12 | J12: 6/6 | K12: 6/9 | L12: 6/12 | M12: 16.6 | N12: 18.7 | O12: -2.1 | P12: -1.35 | Q12: 105 | R12: -2.38 | S12: -1.12 | T12: 106 | U12: -2.38 / -1.12 x 106 | V12: N6 | W12: Full and free | X12: Normal | Y12: Orthophoria | Z12: Slightly temporal | AA12: ~25° esotropia | AB12: Allergic Conjunctivitis | AC12: Surgical excision advised for pterygium | AD12: Satisfactory | AE12: Unsatisfactory | AF12: Easy | AG12: Easy | AH12: Satisfied | AI12: Satisfied | AJ12: Yes | AK12: Yes | AL12: No | AM12: No | AN12: Yes | AO12: No | AP12: Not recorded | AQ12: Yes | AR12: No | AS12: Yes | AT12: Yes | AU12: Not recorded | AV12: Yes | AW12: Yes | AX12: Yes | AY12: Yes
A13: EYE-012 | B13: Rabia Soomro | C13: 28 | D13: Female | E13: Nazimabad, Karachi | F13: 2025-07-17 | G13: 6/9 | H13: 6/9 | I13: 6/24 | J13: 6/12 | K13: 6/6 | L13: 6/9 | M13: 17.1 | N13: 17.2 | O13: 1.77 | P13: -1.19 | Q13: 60 | R13: 1.52 | S13: -1.29 | T13: 51 | U13: +1.52 / -1.29 x 51 | V13: N8 | W13: Full and free | X13: Reduced | Y13: Esophoria | Z13: Central | AA13: Mild ~5° | AB13: Amblyopia | AC13: Follow-up after 3 months advised | AD13: Not recorded | AE13: Unsatisfactory | AF13: Easy | AG13: Very Easy | AH13: Satisfied | AI13: Unsatisfied | AJ13: No | AK13: Yes | AL13: Yes | AM13: Yes | AN13: Not recorded | AO13: No | AP13: No | AQ13: Yes | AR13: Not recorded | AS13: Yes | AT13: No | AU13: No | AV13: Yes | AW13: Yes | AX13: Yes | AY13: No
A14: EYE-013 | B14: Sameer Farooqi | C14: 43 | D14: Male | E14: Federal B Area, Karachi | F14: 2025-08-25 | G14: 6/9 | H14: 6/12 | I14: CF 2m | J14: 6/18 | K14: 6/18 | L14: 6/9 | M14: 16.3 | N14: 16.3 | O14: -1.36 | P14: -1.28 | Q14: 75 | R14: -1.86 | S14: -1.37 | T14: 70 | U14: -1.86 / -1.37 x 70 | V14: N6 | W14: Full and free | X14: Not recorded | Y14: Exotropia | Z14: Central, symmetric | AB14: Amblyopia | AC14: Surgical excision advised for pterygium | AD14: Satisfactory | AE14: Unsatisfactory | AF14: Very Easy | AG14: Very Easy | AH14: Satisfied | AI14: Satisfied | AJ14: Yes | AK14: Yes | AL14: No | AM14: No | AN14: Yes | AO14: No | AP14: No | AQ14: Yes | AR14: Yes | AS14: Yes | AT14: Yes | AU14: Yes | AV14: No | AW14: Yes | AX14: Yes | AY14: Yes
A15: EYE-014 | B15: Rida Sheikh | C15: 35 | D15: Female | E15: Malir, Karachi | F15: 2025-04-26 | G15: 6/24 | H15: 6/6 | I15: 6/18 | J15: CF 1m | K15: 6/12 | L15: 6/12 | M15: 16.8 | N15: 19.4 | O15: -0.3 | P15: -0.97 | Q15: 105 | R15: -0.21 | S15: -1.45 | T15: 104 | U15: -0.21 / -1.45 x 104 | V15: N12 | W15: Restricted | X15: Normal | Y15: Orthophoria | Z15: Central, symmetric | AB15: Corneal Opacity | AC15: Anti-glaucoma eye drops started | AD15: Not recorded | AE15: Unsatisfactory | AF15: Very Easy | AG15: Easy | AH15: Satisfied | AI15: Satisfied | AJ15: No | AK15: Yes | AL15: Yes | AM15: Yes | AN15: No | AO15: No | AP15: No | AQ15: Yes | AR15: No | AS15: Yes | AT15: Yes | AU15: Yes | AV15: Yes | AW15: Yes | AX15: Yes | AY15: No
A16: EYE-015 | B16: Tariq Baloch | C16: 39 | D16: Male | E16: Orangi Town, Karachi | F16: 2024-09-06 | G16: 6/18 | H16: Not done | I16: 6/60 | J16: 6/12 | K16: 6/9 | L16: 6/60 | M16: 23.4 | N16: 23.1 | O16: 0.03 | P16: -1.95 | Q16: 90 | R16: 0.02 | S16: -1.66 | T16: 94 | U16: +0.02 / -1.66 x 94 | V16: N6 | W16: Normal | X16: Normal | Y16: Exophoria | Z16: Central, symmetric | AB16: Glaucoma suspect | AC16: Referred for cataract surgery evaluation | AD16: Unsatisfactory | AE16: Unsatisfactory | AF16: Easy | AG16: Difficult | AH16: Unsatisfied | AI16: Satisfied | AJ16: No | AK16: Yes | AL16: Yes | AM16: Yes | AN16: Yes | AO16: No | AP16: No | AQ16: Yes | AR16: No | AS16: Yes | AT16: Yes | AU16: Yes | AV16: Not recorded | AW16: Yes | AX16: No | AY16: Yes
A17: EYE-016 | B17: Farhan Rizvi | C17: 52 | D17: Male | E17: Liaquatabad, Karachi | F17: 2024-03-23 | G17: 6/9 | H17: 6/12 | I17: 6/18 | J17: 6/24 | K17: Not done | L17: 6/60 | M17: 12.6 | N17: 14.6 | O17: -4.39 | P17: 0 | Q17: 170 | R17: -4.18 | S17: -0.25 | T17: 166 | U17: -4.18 / -0.25 x 166 | V17: N24 | W17: Restricted | X17: Reduced | Y17: Orthophoria | Z17: Central, symmetric | AB17: Strabismus | AC17: Follow-up after 3 months advised | AD17: Unsatisfactory | AE17: Unsatisfactory | AF17: Easy | AG17: Very Easy | AH17: Satisfied | AI17: Satisfied | AJ17: No | AK17: Yes | AL17: Yes | AM17: Not recorded | AN17: Yes | AO17: No | AP17: No | AQ17: Yes | AR17: No | AS17: Yes | AT17: Yes | AU17: Yes | AV17: Yes | AW17: Yes | AX17: Yes | AY17: No
A18: EYE-017 | B18: Qasim Zaidi | C18: 39 | D18: Male | E18: Defence (DHA), Karachi | F18: 2025-01-02 | G18: 6/9 | H18: 6/6 | I18: 6/12 | J18: 6/24 | K18: NI | L18: 6/6 | M18: 13.9 | N18: 11.7 | O18: -0.57 | P18: -0.47 | Q18: 120 | R18: -0.94 | S18: -0.7 | T18: 129 | U18: -0.94 / -0.70 x 129 | V18: N36 | W18: Normal | X18: Reduced | Y18: Orthophoria | Z18: Slightly temporal | AA18: ~10° exotropia | AB18: Dry Eye Disease | AC18: Patching therapy advised for amblyopia | AD18: Satisfactory | AE18: Unsatisfactory | AF18: Difficult | AG18: Difficult | AH18: Satisfied | AI18: Satisfied | AJ18: Yes | AK18: Yes | AL18: Yes | AM18: Yes | AN18: Not recorded | AO18: Yes | AP18: No | AQ18: Yes | AR18: No | AS18: Yes | AT18: Yes | AU18: Yes | AV18: No | AW18: Yes | AX18: No | AY18: Yes
A19: EYE-018 | B19: Waqar Baig | C19: 23 | D19: Male | E19: Gulistan-e-Johar, Karachi | F19: 2025-04-10 | G19: 6/24 | H19: 6/12 | I19: CF 2m | J19: 6/24 | K19: NI | L19: 6/6 | M19: 14.5 | N19: 15.6 | O19: -3.95 | P19: 0 | Q19: 60 | R19: -3.87 | S19: -0.4 | T19: 61 | U19: -3.87 / -0.40 x 61 | V19: N6 | W19: Full and free | X19: Normal | Y19: Orthophoria | Z19: Central, symmetric | AB19: Normal Examination | AC19: Referred for cataract surgery evaluation | AD19: Satisfactory | AE19: Not recorded | AF19: Difficult | AG19: Easy | AH19: Satisfied | AI19: Unsatisfied | AJ19: Yes | AK19: Yes | AL19: Yes | AM19: Yes | AN19: Yes | AO19: No | AP19: No | AQ19: Yes | AR19: No | AS19: Yes | AT19: No | AU19: Not recorded | AV19: Yes | AW19: No | AX19: Yes | AY19: No
A20: EYE-019 | B20: Danish Abbasi | C20: 42 | D20: Not recorded | E20: Nazimabad, Karachi | F20: 2024-09-06 | G20: 6/36 | H20: NI | I20: 6/18 | J20: 6/9 | K20: 6/12 | L20: 6/36 | M20: 18 | N20: 16.3 | O20: -4.18 | P20: -0.63 | Q20: 20 | R20: -4 | S20: -0.57 | T20: 22 | U20: -4.00 / -0.57 x 22 | V20: N10 | W20: Normal | X20: Normal | Y20: Orthophoria | Z20: Central, symmetric | AB20: Allergic Conjunctivitis | AC20: Surgical excision advised for pterygium | AD20: Not recorded | AE20: Unsatisfactory | AF20: Easy | AG20: Easy | AH20: Unsatisfied | AI20: Satisfied | AJ20: Yes | AK20: Yes | AL20: No | AM20: Yes | AN20: Yes | AO20: Yes | AP20: No | AQ20: Yes | AR20: No | AS20: Yes | AT20: Yes | AU20: Yes | AV20: Not recorded | AW20: No | AX20: Yes | AY20: Yes
A21: EYE-020 | B21: Zahid Iqbal | C21: 25 | D21: Male | E21: Federal B Area, Karachi | F21: 2024-10-28 | G21: 6/12 | H21: NI | I21: 6/24 | J21: 6/12 | K21: 6/6 | L21: 6/60 | M21: 16.2 | N21: 16.6 | O21: -2.61 | P21: -0.47 | Q21: 90 | R21: -1.96 | S21: -0.77 | T21: 93 | U21: -1.96 / -0.77 x 93 | V21: N18 | W21: Full and free | X21: Normal | Y21: Esophoria | Z21: Central | AB21: Amblyopia | AC21: Surgical excision advised for pterygium | AD21: Not recorded | AE21: Satisfactory | AF21: Easy | AG21: Difficult | AH21: Unsatisfied | AI21: Satisfied | AJ21: Yes | AK21: No | AL21: No | AM21: Yes | AN21: Yes | AO21: Yes | AP21: No | AQ21: Yes | AR21: No | AS21: Yes | AT21: Yes | AU21: Yes | AV21: Yes | AW21: Yes | AX21: Yes | AY21: Yes
A22: EYE-021 | B22: Hafsa Hussain | C22: 20 | D22: Female | E22: Lyari, Karachi | F22: 2024-01-30 | G22: 6/9 | H22: Not done | I22: 6/9 | J22: 6/36 | K22: 6/9 | L22: 6/6 | M22: 18 | N22: 19.6 | O22: -2.88 | P22: -0.53 | Q22: 20 | R22: -2.54 | S22: -0.32 | T22: 31 | U22: -2.54 / -0.32 x 31 | V22: N24 | W22: Full and free | X22: Normal | Y22: Orthophoria | Z22: Central | AB22: Conjunctivitis | AC22: Reassurance and routine follow-up | AD22: Not recorded | AE22: Unsatisfactory | AF22: Easy | AG22: Difficult | AH22: Satisfied | AI22: Satisfied | AJ22: Yes | AK22: No | AL22: No | AM22: No | AN22: Not recorded | AO22: No | AP22: No | AQ22: Yes | AR22: No | AS22: Yes | AT22: Yes | AU22: Yes | AV22: Yes | AW22: No | AX22: Yes | AY22: Yes
A23: EYE-022 | B23: Haris Ahmed | C23: 33 | D23: Male | E23: Landhi, Karachi | F23: 2025-03-22 | G23: 6/12 | H23: 6/9 | I23: 6/12 | J23: 6/6 | K23: 6/9 | L23: 6/24 | M23: 13.1 | N23: 11.9 | O23: -2.87 | P23: -0.59 | Q23: 0 | R23: -2.9 | S23: -0.52 | T23: 4 | U23: -2.90 / -0.52 x 4 | V23: N36 | W23: Restricted | X23: Normal | Y23: Orthophoria | Z23: Central, symmetric | AB23: Normal Examination | AC23: Referred to retina specialist | AD23: Satisfactory | AE23: Unsatisfactory | AF23: Difficult | AG23: Very Easy | AH23: Satisfied | AI23: Satisfied | AJ23: Yes | AK23: Yes | AL23: No | AM23: Yes | AN23: Yes | AO23: No | AP23: No | AQ23: No | AR23: Yes | AS23: Yes | AT23: Yes | AU23: Yes | AV23: Yes | AW23: Yes | AX23: Yes | AY23: Yes
A24: EYE-023 | B24: Rabia Iqbal | C24: 38 | D24: Female | E24: Korangi, Karachi | F24: 2024-03-16 | G24: 6/12 | H24: 6/9 | I24: 6/24 | J24: 6/6 | K24: 6/6 | L24: HM | M24: 20.2 | N24: 19.8 | O24: 6 | P24: -1.67 | Q24: 45 | R24: 6 | S24: -1.94 | T24: 47 | U24: +6.00 / -1.94 x 47 | V24: N10 | W24: Full and free | X24: Reduced | Y24: Hypertropia | Z24: Central, symmetric | AB24: Strabismus | AC24: Spectacle correction reviewed and updated | AD24: Unsatisfactory | AE24: Satisfactory | AF24: Easy | AG24: Easy | AH24: Satisfied | AI24: Not recorded | AJ24: No | AK24: Yes | AL24: No | AM24: No | AN24: No | AO24: No | AP24: Not recorded | AQ24: No | AR24: No | AS24: No | AT24: Yes | AU24: Yes | AV24: Yes | AW24: Yes | AX24: Yes | AY24: No
A25: EYE-024 | B25: Erum Farooqi | C25: 33 | D25: Female | E25: Orangi Town, Karachi | F25: 2025-07-26 | G25: 6/24 | H25: 6/6 | I25: CF 2m | J25: 6/9 | K25: 6/18 | L25: PL+ | M25: 17.8 | N25: 18.5 | O25: -0.94 | P25: -2.26 | Q25: 75 | R25: -1.24 | S25: -2.37 | T25: 80 | U25: -1.24 / -2.37 x 80 | V25: N12 | W25: Normal | X25: Reduced | Y25: Orthophoria | Z25: Slightly temporal | AA25: ~10° exotropia | AB25: Pterygium | AC25: Topical antibiotic eye drops advised | AD25: Satisfactory | AE25: Not recorded | AF25: Easy | AG25: Very Easy | AH25: Unsatisfied | AI25: Unsatisfied | AJ25: No | AK25: Yes | AL25: No | AM25: No | AN25: Yes | AO25: No | AP25: No | AQ25: Yes | AR25: No | AS25: Yes | AT25: Yes | AU25: Yes | AV25: Yes | AW25: Yes | AX25: Yes | AY25: Yes
A26: EYE-025 | B26: Kashif Ahmed | C26: 41 | D26: Male | E26: Orangi Town, Karachi | F26: 2025-05-07 | G26: 6/12 | H26: 6/18 | I26: 6/6 | J26: CF 1m | K26: 6/9 | L26: 6/6 | M26: 11.5 | N26: 11.7 | O26: 0.25 | P26: -0.76 | Q26: 170 | R26: -0.06 | S26: -0.75 | T26: 163 | U26: -0.06 / -0.75 x 163 | V26: N6 | W26: Full and free | X26: Not recorded | Y26: Esophoria | Z26: Central, symmetric | AB26: Refractive Error | AC26: Spectacle correction reviewed and updated | AD26: Not recorded | AE26: Not recorded | AF26: Easy | AG26: Easy | AH26: Unsatisfied | AI26: Unsatisfied | AJ26: Yes | AK26: Yes | AL26: Yes | AM26: Yes | AN26: Yes | AO26: Yes | AP26: Not recorded | AQ26: Yes | AR26: No | AS26: Yes | AT26: Yes | AU26: Yes | AV26: Yes | AW26: No | AX26: Yes | AY26: Yes
A27: EYE-026 | B27: Faisal Farooqi | C27: 44 | D27: Male | E27: Federal B Area, Karachi | F27: 2025-03-15 | G27: 6/18 | H27: 6/9 | I27: 6/6 | J27: 6/9 | K27: 6/12 | L27: HM | M27: 17.3 | N27: 18.8 | O27: 1.99 | P27: -1.74 | Q27: 0 | R27: 1.51 | S27: -1.61 | T27: 3 | U27: +1.51 / -1.61 x 3 | V27: N6 | W27: Normal | X27: Normal | Y27: Orthophoria | Z27: Central, symmetric | AB27: Refractive Error | AC27: Spectacle correction reviewed and updated | AD27: Satisfactory | AE27: Unsatisfactory | AF27: Easy | AG27: Difficult | AH27: Satisfied | AI27: Satisfied | AJ27: Yes | AK27: Not recorded | AL27: Yes | AM27: Yes | AN27: Yes | AO27: Yes | AP27: No | AQ27: Yes | AR27: No | AS27: Yes | AT27: Yes | AU27: Yes | AV27: Not recorded | AW27: Yes | AX27: Yes | AY27: Yes
A28: EYE-027 | B28: Omar Soomro | C28: 47 | D28: Male | E28: Gulistan-e-Johar, Karachi | F28: 2025-02-13 | G28: 6/12 | H28: 6/9 | I28: 6/24 | J28: CF 2m | K28: 6/6 | L28: 6/12 | M28: 27.8 | N28: 28.6 | O28: 2.2 | P28: -0.31 | Q28: 150 | R28: 2.53 | S28: -0.39 | T28: 154 | U28: +2.53 / -0.39 x 154 | V28: N12 | W28: Normal | X28: Normal | Y28: Orthophoria | Z28: Slightly nasal | AA28: ~20° esotropia | AB28: Pterygium | AC28: Patching therapy advised for amblyopia | AD28: Satisfactory | AE28: Satisfactory | AF28: Easy | AG28: Very Easy | AH28: Unsatisfied | AI28: Satisfied | AJ28: No | AK28: Yes | AL28: No | AM28: Yes | AN28: Yes | AO28: No | AP28: No | AQ28: Yes | AR28: No | AS28: No | AT28: Yes | AU28: Yes | AV28: Yes | AW28: Yes | AX28: Yes | AY28: No
A29: EYE-028 | B29: Ali Sheikh | C29: 24 | D29: Not recorded | E29: Nazimabad, Karachi | F29: 2025-05-26 | G29: 6/12 | H29: 6/6 | I29: 6/12 | J29: 6/18 | K29: 6/6 | L29: PL+ | M29: 14.7 | N29: 14 | O29: -0.54 | P29: -2.58 | Q29: 105 | R29: 0.27 | S29: -2.41 | T29: 95 | U29: +0.27 / -2.41 x 95 | V29: N8 | W29: Restricted | X29: Normal | Y29: Orthophoria | Z29: Central, symmetric | AA29: Mild ~5° | AB29: Allergic Conjunctivitis | AC29: Reassurance and routine follow-up | AD29: Satisfactory | AE29: Satisfactory | AF29: Easy | AG29: Very Easy | AH29: Satisfied | AI29: Satisfied | AJ29: No | AK29: Yes | AL29: Yes | AM29: No | AN29: Yes | AO29: No | AP29: No | AQ29: Yes | AR29: No | AS29: Not recorded | AT29: Yes | AU29: Yes | AV29: Yes | AW29: No | AX29: Yes | AY29: No
A30: EYE-029 | B30: Rida Anwar | C30: 29 | D30: Female | E30: PECHS, Karachi | F30: 2025-08-24 | G30: 6/36 | H30: 6/9 | I30: 6/60 | J30: 6/6 | K30: NI | L30: 6/18 | M30: 19 | N30: 19.1 | O30: -3.55 | P30: -0.29 | Q30: 20 | R30: -3.8 | S30: -0.47 | T30: 21 | U30: -3.80 / -0.47 x 21 | V30: N10 | W30: Full and free | X30: Reduced | Y30: Orthophoria | Z30: Central, symmetric | AB30: Pterygium | AC30: Referred to retina specialist | AD30: Unsatisfactory | AE30: Satisfactory | AF30: Difficult | AG30: Very Easy | AH30: Satisfied | AI30: Satisfied | AJ30: No | AK30: Yes | AL30: Yes | AM30: Yes | AN30: Yes | AO30: No | AP30: No | AQ30: Not recorded | AR30: Yes | AS30: Yes | AT30: Yes | AU30: Yes | AV30: Not recorded | AW30: Yes | AX30: Yes | AY30: No
A31: EYE-030 | B31: Faisal Abbasi | C31: 38 | D31: Male | E31: Gulistan-e-Johar, Karachi | F31: 2024-11-22 | G31: HM | H31: 6/9 | I31: 6/18 | J31: 6/9 | K31: NI | L31: 6/6 | M31: 13.4 | N31: 16.4 | O31: 0.9 | P31: -0.73 | Q31: 150 | R31: 0.19 | S31: -0.9 | T31: 155 | U31: +0.19 / -0.90 x 155 | V31: N18 | W31: Full and free | X31: Normal | Y31: Orthophoria | Z31: Central, symmetric | AB31: Dry Eye Disease | AC31: Anti-glaucoma eye drops started | AD31: Not recorded | AE31: Not recorded | AF31: Easy | AG31: Very Easy | AH31: Unsatisfied | AI31: Satisfied | AJ31: No | AK31: No | AL31: Yes | AM31: No | AN31: Yes | AO31: Yes | AP31: No | AQ31: Yes | AR31: Not recorded | AS31: Yes | AT31: Yes | AU31: Yes | AV31: Yes | AW31: Yes | AX31: Yes | AY31: Yes
A32: EYE-031 | B32: Danish Rizvi | C32: 23 | D32: Male | E32: Defence (DHA), Karachi | F32: 2025-01-17 | G32: HM | H32: 6/9 | I32: 6/18 | J32: 6/18 | K32: 6/6 | L32: 6/12 | M32: 15.1 | N32: 15.8 | O32: 1.5 | P32: -1.2 | Q32: 160 | R32: 1.08 | S32: -1.32 | T32: 156 | U32: +1.08 / -1.32 x 156 | V32: N6 | W32: Normal | X32: Reduced | Y32: Orthophoria | Z32: Central, symmetric | AB32: Normal Examination | AC32: Patching therapy advised for amblyopia | AD32: Unsatisfactory | AE32: Satisfactory | AF32: Easy | AG32: Easy | AH32: Satisfied | AI32: Satisfied | AJ32: Yes | AK32: Yes | AL32: No | AM32: Yes | AN32: Yes | AO32: Yes | AP32: No | AQ32: Yes | AR32: No | AS32: Yes | AT32: Yes | AU32: Yes | AV32: Yes | AW32: Yes | AX32: Yes | AY32: No
A33: EYE-032 | B33: Imran Soomro | C33: 69 | D33: Male | E33: Lyari, Karachi | F33: 2025-05-28 | G33: 6/18 | H33: NI | I33: 6/24 | J33: 6/12 | K33: 6/18 | L33: 6/18 | M33: 16.8 | N33: 15 | O33: 1.64 | P33: 0 | Q33: 160 | R33: 2.38 | S33: -0.38 | T33: 157 | U33: +2.38 / -0.38 x 157 | V33: N8 | W33: Full and free | X33: Normal | Y33: Hypertropia | Z33: Central | AA33: Mild ~5° | AB33: Corneal Opacity | AC33: Anti-glaucoma eye drops started | AD33: Satisfactory | AE33: Satisfactory | AF33: Easy | AG33: Very Easy | AH33: Satisfied | AI33: Satisfied | AJ33: No | AK33: Yes | AL33: No | AM33: Yes | AN33: No | AO33: No | AP33: No | AQ33: Yes | AR33: No | AS33: Yes | AT33: Yes | AU33: Yes | AV33: Yes | AW33: Yes | AX33: Yes | AY33: Yes
A34: EYE-033 | B34: Amina Raza | C34: 60 | D34: Female | E34: Bahadurabad, Karachi | F34: 2024-09-05 | G34: 6/24 | H34: 6/12 | I34: 6/12 | J34: 6/18 | K34: 6/6 | L34: 6/24 | M34: 13.2 | N34: 13.8 | O34: 1.26 | P34: -0.95 | Q34: 0 | R34: 0.94 | S34: -1.76 | T34: 0 | U34: +0.94 / -1.76 x 0 | V34: N12 | W34: Full and free | X34: Reduced | Y34: Orthophoria | Z34: Central, symmetric | AB34: Corneal Opacity | AC34: Referred to retina specialist | AD34: Satisfactory | AE34: Satisfactory | AF34: Very Easy | AG34: Easy | AH34: Satisfied | AI34: Unsatisfied | AJ34: Yes | AK34: Yes | AL34: No | AM34: Yes | AN34: Yes | AO34: No | AP34: No | AQ34: Yes | AR34: No | AS34: No | AT34: No | AU34: Yes | AV34: Yes | AW34: Yes | AX34: Yes | AY34: No
A35: EYE-034 | B35: Nasir Farooqi | C35: 33 | D35: Male | E35: Nazimabad, Karachi | F35: 2025-08-04 | G35: 6/36 | H35: NI | I35: 6/36 | J35: 6/6 | K35: NI | L35: 6/18 | M35: 11.5 | N35: 13.8 | O35: -4.47 | P35: -0.78 | Q35: 135 | R35: -4.62 | S35: -0.42 | T35: 126 | U35: -4.62 / -0.42 x 126 | V35: N18 | W35: Full and free | X35: Reduced | Y35: Orthophoria | Z35: Central, symmetric | AB35: Amblyopia | AC35: Referred for cataract surgery evaluation | AD35: Satisfactory | AE35: Not recorded | AF35: Very Easy | AG35: Very Easy | AH35: Satisfied | AI35: Satisfied | AJ35: No | AK35: Yes | AL35: Not recorded | AM35: No | AN35: Yes | AO35: No | AP35: No | AQ35: Yes | AR35: No | AS35: Yes | AT35: Yes | AU35: No | AV35: Yes | AW35: Yes | AX35: Yes | AY35: Yes
A36: EYE-035 | B36: Javeria Zaidi | C36: 58 | D36: Female | E36: Bahadurabad, Karachi | F36: 2025-07-03 | G36: 6/6 | H36: 6/9 | I36: 6/24 | J36: 6/60 | K36: 6/18 | L36: 6/12 | M36: 15.5 | N36: 14.1 | O36: 0.45 | P36: -1.44 | Q36: 20 | R36: 0.52 | S36: -1.42 | T36: 17 | U36: +0.52 / -1.42 x 17 | V36: N8 | W36: Normal | X36: Normal | Y36: Orthophoria | Z36: Slightly temporal | AA36: ~25° esotropia | AB36: Refractive Error | AC36: Anti-glaucoma eye drops started | AD36: Unsatisfactory | AE36: Not recorded | AF36: Easy | AG36: Easy | AH36: Satisfied | AI36: Unsatisfied | AJ36: Yes | AK36: Yes | AL36: Yes | AM36: Yes | AN36: No | AO36: No | AP36: Not recorded | AQ36: Yes | AR36: No | AS36: Yes | AT36: Yes | AU36: No | AV36: Yes | AW36: Yes | AX36: Yes | AY36: Yes
A37: EYE-036 | B37: Qasim Raza | C37: 40 | D37: Male | E37: PECHS, Karachi | F37: 2024-09-10 | G37: 6/9 | H37: Not done | I37: 6/6 | J37: 6/9 | K37: 6/18 | L37: 6/36 | M37: 17.6 | N37: 19.8 | O37: -3.97 | P37: -2.66 | Q37: 90 | R37: -3.22 | S37: -2.7 | T37: 93 | U37: -3.22 / -2.70 x 93 | V37: N36 | W37: Full and free | X37: Reduced | Y37: Orthophoria | Z37: Central, symmetric | AB37: Strabismus | AC37: Lubricating eye drops prescribed | AD37: Satisfactory | AE37: Not recorded | AF37: Difficult | AG37: Very Easy | AH37: Satisfied | AI37: Not recorded | AJ37: No | AK37: Not recorded | AL37: No | AM37: Yes | AN37: Yes | AO37: No | AP37: No | AQ37: Yes | AR37: No | AS37: Yes | AT37: Yes | AU37: Yes | AV37: No | AW37: Yes | AX37: Yes | AY37: No
A38: EYE-037 | B38: Kiran Farooqi | C38: 43 | D38: Female | E38: Lyari, Karachi | F38: 2024-05-27 | G38: 6/12 | H38: 6/9 | I38: 6/18 | J38: 6/6 | K38: 6/9 | L38: 6/12 | M38: 13.5 | N38: 13.2 | O38: -2.03 | P38: -0.14 | Q38: 160 | R38: -2.24 | S38: -0.05 | T38: 155 | U38: -2.24 / -0.05 x 155 | V38: N36 | W38: Mildly restricted | X38: Not recorded | Y38: Orthophoria | Z38: Central, symmetric | AB38: Pterygium | AC38: Spectacles prescribed | AD38: Not recorded | AE38: Satisfactory | AF38: Very Easy | AG38: Very Easy | AH38: Satisfied | AI38: Satisfied | AJ38: No | AK38: Not recorded | AL38: No | AM38: No | AN38: Yes | AO38: No | AP38: No | AQ38: Yes | AR38: No | AS38: Yes | AT38: Yes | AU38: Yes | AV38: Yes | AW38: Yes | AX38: No | AY38: No
A39: EYE-038 | B39: Ayesha Hussain | C39: 54 | D39: Female | E39: Federal B Area, Karachi | F39: 2025-07-20 | G39: 6/18 | H39: 6/6 | I39: 6/9 | J39: 6/24 | K39: 6/6 | L39: 6/18 | M39: 16.5 | N39: 17.6 | O39: 0.89 | P39: -1.4 | Q39: 180 | R39: 0.6 | S39: -1.21 | T39: 180 | U39: +0.60 / -1.21 x 180 | V39: N18 | W39: Restricted | X39: Normal | Y39: Esotropia | Z39: Central, symmetric | AB39: Allergic Conjunctivitis | AC39: Lubricating eye drops prescribed | AD39: Satisfactory | AE39: Satisfactory | AF39: Difficult | AG39: Very Easy | AH39: Satisfied | AI39: Satisfied | AJ39: No | AK39: Yes | AL39: Yes | AM39: No | AN39: Yes | AO39: Yes | AP39: Yes | AQ39: Not recorded | AR39: No | AS39: Yes | AT39: Yes | AU39: Yes | AV39: No | AW39: Yes | AX39: Yes | AY39: Not recorded
A40: EYE-039 | B40: Yusra Qureshi | C40: 37 | D40: Female | E40: Nazimabad, Karachi | F40: 2024-09-03 | G40: 6/18 | H40: 6/9 | I40: 6/6 | J40: 6/9 | K40: NI | L40: CF 2m | M40: 15.9 | N40: 17.7 | O40: -2.29 | P40: -1.08 | Q40: 30 | R40: -2.1 | S40: -1.13 | T40: 36 | U40: -2.10 / -1.13 x 36 | V40: N10 | W40: Full and free | X40: Normal | Y40: Exotropia | Z40: Central, symmetric | AB40: Pterygium | AC40: Spectacle correction reviewed and updated | AD40: Not recorded | AE40: Unsatisfactory | AF40: Easy | AG40: Very Easy | AH40: Satisfied | AI40: Satisfied | AJ40: Not recorded | AK40: Yes | AL40: No | AM40: Yes | AN40: Yes | AO40: No | AP40: No | AQ40: Yes | AR40: No | AS40: Yes | AT40: Yes | AU40: Yes | AV40: Yes | AW40: Yes | AX40: Yes | AY40: No
...

Sheet Dashboard
A1: SMART EYE CAMERA vs SLIT LAMP — RESEARCH DASHBOARD
B3: Total Study Participants | D3: Mean Age | F3: Slit Lamp Satisfactory % | H3: Smart Camera Satisfactory %
B4: =COUNTA('Patient Data'!A2:A1000) -> 51 | D4: =IFERROR(AVERAGE('Patient Data'!C2:C1000),0) -> 37.647059 | F4: =IFERROR(COUNTIF('Patient Data'!AD2:AD1000,"Satisfactory")/(COUNTIF('Patient Data'!AD2:AD1000,"Satisfactory")+COUNTIF('Patient Data'!AD2:AD1000,"Unsatisfactory")),0) -> 0.69444444 | H4: =IFERROR(COUNTIF('Patient Data'!AE2:AE1000,"Satisfactory")/(COUNTIF('Patient Data'!AE2:AE1000,"Satisfactory")+COUNTIF('Patient Data'!AE2:AE1000,"Unsatisfactory")),0) -> 0.53846154
A7: Examination Outcome by Device
A8: Outcome | B8: Slit Lamp | C8: Smart Camera
A9: Satisfactory | B9: =COUNTIF('Patient Data'!AD2:AD1000,"Satisfactory") -> 25 | C9: =COUNTIF('Patient Data'!AE2:AE1000,"Satisfactory") -> 21
A10: Unsatisfactory | B10: =COUNTIF('Patient Data'!AD2:AD1000,"Unsatisfactory") -> 11 | C10: =COUNTIF('Patient Data'!AE2:AE1000,"Unsatisfactory") -> 18
A12: Gender Distribution
A13: Gender | B13: Count
A14: Male | B14: =COUNTIF('Patient Data'!D2:D1000,"Male") -> 20
A15: Female | B15: =COUNTIF('Patient Data'!D2:D1000,"Female") -> 28
A16: Other | B16: =COUNTIF('Patient Data'!D2:D1000,"Other") -> 0
A17: Not recorded | B17: =COUNTIF('Patient Data'!D2:D1000,"Not recorded") -> 3
A19: Age Distribution
A20: Age Range | B20: Count
A21: 0-10 | B21: =COUNTIFS('Patient Data'!C2:C1000,">=0",'Patient Data'!C2:C1000,"<=10") -> 1
A22: 11-20 | B22: =COUNTIFS('Patient Data'!C2:C1000,">=11",'Patient Data'!C2:C1000,"<=20") -> 3
A23: 21-30 | B23: =COUNTIFS('Patient Data'!C2:C1000,">=21",'Patient Data'!C2:C1000,"<=30") -> 12
A24: 31-40 | B24: =COUNTIFS('Patient Data'!C2:C1000,">=31",'Patient Data'!C2:C1000,"<=40") -> 15
A25: 41-50 | B25: =COUNTIFS('Patient Data'!C2:C1000,">=41",'Patient Data'!C2:C1000,"<=50") -> 10
A26: 51-60 | B26: =COUNTIFS('Patient Data'!C2:C1000,">=51",'Patient Data'!C2:C1000,"<=60") -> 9
A27: 61-70 | B27: =COUNTIFS('Patient Data'!C2:C1000,">=61",'Patient Data'!C2:C1000,"<=70") -> 1
A28: 71-80 | B28: =COUNTIFS('Patient Data'!C2:C1000,">=71",'Patient Data'!C2:C1000,"<=80") -> 0
A29: 81-90 | B29: =COUNTIFS('Patient Data'!C2:C1000,">=81",'Patient Data'!C2:C1000,"<=90") -> 0
A30: 91+ | B30: =COUNTIFS('Patient Data'!C2:C1000,">=91") -> 0
A32: Diagnosis Distribution
A33: Diagnosis | B33: Count
A34: Refractive Error | B34: =COUNTIF('Patient Data'!AB2:AB1000,"Refractive Error") -> 6
A35: Cataract | B35: =COUNTIF('Patient Data'!AB2:AB1000,"Cataract") -> 5
A36: Glaucoma suspect | B36: =COUNTIF('Patient Data'!AB2:AB1000,"Glaucoma suspect") -> 1
A37: Conjunctivitis | B37: =COUNTIF('Patient Data'!AB2:AB1000,"Conjunctivitis") -> 3
A38: Strabismus | B38: =COUNTIF('Patient Data'!AB2:AB1000,"Strabismus") -> 4
A39: Diabetic Retinopathy | B39: =COUNTIF('Patient Data'!AB2:AB1000,"Diabetic Retinopathy") -> 0
A40: Pterygium | B40: =COUNTIF('Patient Data'!AB2:AB1000,"Pterygium") -> 6
A41: Normal Examination | B41: =COUNTIF('Patient Data'!AB2:AB1000,"Normal Examination") -> 5
A42: Dry Eye Disease | B42: =COUNTIF('Patient Data'!AB2:AB1000,"Dry Eye Disease") -> 3
A43: Amblyopia | B43: =COUNTIF('Patient Data'!AB2:AB1000,"Amblyopia") -> 5
A44: Allergic Conjunctivitis | B44: =COUNTIF('Patient Data'!AB2:AB1000,"Allergic Conjunctivitis") -> 7
A45: Corneal Opacity | B45: =COUNTIF('Patient Data'!AB2:AB1000,"Corneal Opacity") -> 6
A46: Other / not listed above | B46: =MAX(0,COUNTA('Patient Data'!AB2:AB1000)-SUM(B34:B45)) -> 0
...

Sheet Clinical Analysis
A1: CLINICAL MEASUREMENT COMPARISON
A3: Summary Statistics — Slit Lamp vs Smart Camera
A4: Parameter | B4: Device | C4: N | D4: Mean | E4: SD
A5: IOP (mmHg) | B5: Slit Lamp | C5: =COUNT('Patient Data'!M2:M1000) -> 51 | D5: =IFERROR(AVERAGE('Patient Data'!M2:M1000),"") -> 16.284314 | E5: =IFERROR(STDEV('Patient Data'!M2:M1000),"") -> 3.1402148
A6: IOP (mmHg) | B6: Smart Camera | C6: =COUNT('Patient Data'!N2:N1000) -> 51 | D6: =IFERROR(AVERAGE('Patient Data'!N2:N1000),"") -> 16.576471 | E6: =IFERROR(STDEV('Patient Data'!N2:N1000),"") -> 3.2866146
A7: SPH (diopters) | B7: Slit Lamp | C7: =COUNT('Patient Data'!O2:O1000) -> 51 | D7: =IFERROR(AVERAGE('Patient Data'!O2:O1000),"") -> -0.76058824 | E7: =IFERROR(STDEV('Patient Data'!O2:O1000),"") -> 2.5637725
A8: SPH (diopters) | B8: Smart Camera | C8: =COUNT('Patient Data'!R2:R1000) -> 51 | D8: =IFERROR(AVERAGE('Patient Data'!R2:R1000),"") -> -0.78882353 | E8: =IFERROR(STDEV('Patient Data'!R2:R1000),"") -> 2.5468755
A9: CYL (diopters) | B9: Slit Lamp | C9: =COUNT('Patient Data'!P2:P1000) -> 51 | D9: =IFERROR(AVERAGE('Patient Data'!P2:P1000),"") -> -1.0941176 | E9: =IFERROR(STDEV('Patient Data'!P2:P1000),"") -> 0.71461927
A10: CYL (diopters) | B10: Smart Camera | C10: =COUNT('Patient Data'!S2:S1000) -> 51 | D10: =IFERROR(AVERAGE('Patient Data'!S2:S1000),"") -> -1.1505882 | E10: =IFERROR(STDEV('Patient Data'!S2:S1000),"") -> 0.73568855
A11: Axis (degrees) | B11: Slit Lamp | C11: =COUNT('Patient Data'!Q2:Q1000) -> 51 | D11: =IFERROR(AVERAGE('Patient Data'!Q2:Q1000),"") -> 90.098039 | E11: =IFERROR(STDEV('Patient Data'!Q2:Q1000),"") -> 60.510249
A12: Axis (degrees) | B12: Smart Camera | C12: =COUNT('Patient Data'!T2:T1000) -> 51 | D12: =IFERROR(AVERAGE('Patient Data'!T2:T1000),"") -> 90.313725 | E12: =IFERROR(STDEV('Patient Data'!T2:T1000),"") -> 58.612794
A14: Paired t-test (Slit Lamp vs Smart Camera)
A15: Parameter | B15: Mean Difference | C15: p-value (2-tailed) | D15: Interpretation
A16: IOP (mmHg) | B16: =IFERROR(AVERAGE('Patient Data'!M2:M1000)-AVERAGE('Patient Data'!N2:N1000),"") -> -0.29215686 | C16: =IFERROR(TTEST('Patient Data'!M2:M1000,'Patient Data'!N2:N1000,2,1),"") -> 0.14741641 | D16: =IF(C16="","",IF(C16<0.05,"Significant difference (p<0.05)","No significant difference")) -> No significant difference
A17: SPH (diopters) | B17: =IFERROR(AVERAGE('Patient Data'!O2:O1000)-AVERAGE('Patient Data'!R2:R1000),"") -> 0.028235294 | C17: =IFERROR(TTEST('Patient Data'!O2:O1000,'Patient Data'!R2:R1000,2,1),"") -> 0.57454558 | D17: =IF(C17="","",IF(C17<0.05,"Significant difference (p<0.05)","No significant difference")) -> No significant difference
A18: CYL (diopters) | B18: =IFERROR(AVERAGE('Patient Data'!P2:P1000)-AVERAGE('Patient Data'!S2:S1000),"") -> 0.056470588 | C18: =IFERROR(TTEST('Patient Data'!P2:P1000,'Patient Data'!S2:S1000,2,1),"") -> 0.10839984 | D18: =IF(C18="","",IF(C18<0.05,"Significant difference (p<0.05)","No significant difference")) -> No significant difference
A19: Axis (degrees) | B19: =IFERROR(AVERAGE('Patient Data'!Q2:Q1000)-AVERAGE('Patient Data'!T2:T1000),"") -> -0.21568627 | C19: =IFERROR(TTEST('Patient Data'!Q2:Q1000,'Patient Data'!T2:T1000,2,1),"") -> 0.78458323 | D19: =IF(C19="","",IF(C19<0.05,"Significant difference (p<0.05)","No significant difference")) -> No significant difference
A21: Note: p-value uses Excel's paired-sample TTEST function. A value below 0.05 suggests the two devices give measurably different readings for that parameter, on average.
A23: Mean Comparison Chart
A24: Parameter | B24: Slit Lamp Mean | C24: Smart Camera Mean
A25: IOP (mmHg) | B25: =IFERROR(AVERAGE('Patient Data'!M2:M1000),0) -> 16.284314 | C25: =IFERROR(AVERAGE('Patient Data'!N2:N1000),0) -> 16.576471
A26: SPH (diopters) | B26: =IFERROR(AVERAGE('Patient Data'!O2:O1000),0) -> -0.76058824 | C26: =IFERROR(AVERAGE('Patient Data'!R2:R1000),0) -> -0.78882353
A27: CYL (diopters) | B27: =IFERROR(AVERAGE('Patient Data'!P2:P1000),0) -> -1.0941176 | C27: =IFERROR(AVERAGE('Patient Data'!S2:S1000),0) -> -1.1505882
A28: Axis (degrees) | B28: =IFERROR(AVERAGE('Patient Data'!Q2:Q1000),0) -> 90.098039 | C28: =IFERROR(AVERAGE('Patient Data'!T2:T1000),0) -> 90.313725

Sheet Technical Comparison
A1: TECHNICAL / USABILITY COMPARISON
A2: "Positive" = Very Easy (Convenience), Satisfied (Accuracy), or Yes (all other rows). For "External Light Source", Yes means the device NEEDS an external light — a LOWER % is the better result for that one row.
A4: 10 Usability Parameters
A5: Parameter | B5: Slit Positive n | C5: Slit Total | D5: Slit % | E5: Camera Positive n | F5: Camera Total | G5: Camera %
A6: 1. Convenience / Ease | B6: =COUNTIF('Patient Data'!AF2:AF1000,"Very Easy") -> 11 | C6: =COUNTIFS('Patient Data'!AF2:AF1000,"<>Not recorded",'Patient Data'!AF2:AF1000,"<>") -> 51 | D6: =IFERROR(B6/C6,0) -> 0.21568627 | E6: =COUNTIF('Patient Data'!AG2:AG1000,"Very Easy") -> 27 | F6: =COUNTIFS('Patient Data'!AG2:AG1000,"<>Not recorded",'Patient Data'!AG2:AG1000,"<>") -> 51 | G6: =IFERROR(E6/F6,0) -> 0.52941176
A7: 2. Accuracy & Clarity | B7: =COUNTIF('Patient Data'!AH2:AH1000,"Satisfied") -> 40 | C7: =COUNTIFS('Patient Data'!AH2:AH1000,"<>Not recorded",'Patient Data'!AH2:AH1000,"<>") -> 51 | D7: =IFERROR(B7/C7,0) -> 0.78431373 | E7: =COUNTIF('Patient Data'!AI2:AI1000,"Satisfied") -> 38 | F7: =COUNTIFS('Patient Data'!AI2:AI1000,"<>Not recorded",'Patient Data'!AI2:AI1000,"<>") -> 49 | G7: =IFERROR(E7/F7,0) -> 0.7755102
A8: 3. Time Efficiency | B8: =COUNTIF('Patient Data'!AJ2:AJ1000,"Yes") -> 21 | C8: =COUNTIFS('Patient Data'!AJ2:AJ1000,"<>Not recorded",'Patient Data'!AJ2:AJ1000,"<>") -> 48 | D8: =IFERROR(B8/C8,0) -> 0.4375 | E8: =COUNTIF('Patient Data'!AK2:AK1000,"Yes") -> 42 | F8: =COUNTIFS('Patient Data'!AK2:AK1000,"<>Not recorded",'Patient Data'!AK2:AK1000,"<>") -> 48 | G8: =IFERROR(E8/F8,0) -> 0.875
A9: 4. Training & Learning Curve | B9: =COUNTIF('Patient Data'!AL2:AL1000,"Yes") -> 23 | C9: =COUNTIFS('Patient Data'!AL2:AL1000,"<>Not recorded",'Patient Data'!AL2:AL1000,"<>") -> 49 | D9: =IFERROR(B9/C9,0) -> 0.46938776 | E9: =COUNTIF('Patient Data'!AM2:AM1000,"Yes") -> 32 | F9: =COUNTIFS('Patient Data'!AM2:AM1000,"<>Not recorded",'Patient Data'!AM2:AM1000,"<>") -> 49 | G9: =IFERROR(E9/F9,0) -> 0.65306122
A10: 5. External Light Source | B10: =COUNTIF('Patient Data'!AN2:AN1000,"Yes") -> 42 | C10: =COUNTIFS('Patient Data'!AN2:AN1000,"<>Not recorded",'Patient Data'!AN2:AN1000,"<>") -> 47 | D10: =IFERROR(B10/C10,0) -> 0.89361702 | E10: =COUNTIF('Patient Data'!AO2:AO1000,"Yes") -> 13 | F10: =COUNTIFS('Patient Data'!AO2:AO1000,"<>Not recorded",'Patient Data'!AO2:AO1000,"<>") -> 51 | G10: =IFERROR(E10/F10,0) -> 0.25490196
A11: 6. Portability | B11: =COUNTIF('Patient Data'!AP2:AP1000,"Yes") -> 4 | C11: =COUNTIFS('Patient Data'!AP2:AP1000,"<>Not recorded",'Patient Data'!AP2:AP1000,"<>") -> 44 | D11: =IFERROR(B11/C11,0) -> 0.090909091 | E11: =COUNTIF('Patient Data'!AQ2:AQ1000,"Yes") -> 45 | F11: =COUNTIFS('Patient Data'!AQ2:AQ1000,"<>Not recorded",'Patient Data'!AQ2:AQ1000,"<>") -> 48 | G11: =IFERROR(E11/F11,0) -> 0.9375
A12: 7. Recording & Storage | B12: =COUNTIF('Patient Data'!AR2:AR1000,"Yes") -> 8 | C12: =COUNTIFS('Patient Data'!AR2:AR1000,"<>Not recorded",'Patient Data'!AR2:AR1000,"<>") -> 49 | D12: =IFERROR(B12/C12,0) -> 0.16326531 | E12: =COUNTIF('Patient Data'!AS2:AS1000,"Yes") -> 46 | F12: =COUNTIFS('Patient Data'!AS2:AS1000,"<>Not recorded",'Patient Data'!AS2:AS1000,"<>") -> 50 | G12: =IFERROR(E12/F12,0) -> 0.92
A13: 8. Clinical Examination | B13: =COUNTIF('Patient Data'!AT2:AT1000,"Yes") -> 48 | C13: =COUNTIFS('Patient Data'!AT2:AT1000,"<>Not recorded",'Patient Data'!AT2:AT1000,"<>") -> 51 | D13: =IFERROR(B13/C13,0) -> 0.94117647 | E13: =COUNTIF('Patient Data'!AU2:AU1000,"Yes") -> 42 | F13: =COUNTIFS('Patient Data'!AU2:AU1000,"<>Not recorded",'Patient Data'!AU2:AU1000,"<>") -> 48 | G13: =IFERROR(E13/F13,0) -> 0.875
A14: 9. Resolution | B14: =COUNTIF('Patient Data'!AV2:AV1000,"Yes") -> 41 | C14: =COUNTIFS('Patient Data'!AV2:AV1000,"<>Not recorded",'Patient Data'!AV2:AV1000,"<>") -> 47 | D14: =IFERROR(B14/C14,0) -> 0.87234043 | E14: =COUNTIF('Patient Data'!AW2:AW1000,"Yes") -> 38 | F14: =COUNTIFS('Patient Data'!AW2:AW1000,"<>Not recorded",'Patient Data'!AW2:AW1000,"<>") -> 49 | G14: =IFERROR(E14/F14,0) -> 0.7755102
A15: 10. Field of View | B15: =COUNTIF('Patient Data'!AX2:AX1000,"Yes") -> 43 | C15: =COUNTIFS('Patient Data'!AX2:AX1000,"<>Not recorded",'Patient Data'!AX2:AX1000,"<>") -> 51 | D15: =IFERROR(B15/C15,0) -> 0.84313725 | E15: =COUNTIF('Patient Data'!AY2:AY1000,"Yes") -> 26 | F15: =COUNTIFS('Patient Data'!AY2:AY1000,"<>Not recorded",'Patient Data'!AY2:AY1000,"<>") -> 48 | G15: =IFERROR(E15/F15,0) -> 0.54166667

Sheet Statistical Tests
A1: STATISTICAL TESTS — SLIT LAMP vs SMART CAMERA
A3: 1. McNemar Test — Examination Outcome (paired, binary)
A4: Tests whether the two devices disagree on Satisfactory/Unsatisfactory more than chance would predict.
B5: Camera: Satisfactory | C5: Camera: Unsatisfactory
A6: Slit: Satisfactory | B6: =COUNTIFS('Patient Data'!AD2:AD1000,"Satisfactory",'Patient Data'!AE2:AE1000,"Satisfactory") -> 10 | C6: =COUNTIFS('Patient Data'!AD2:AD1000,"Satisfactory",'Patient Data'!AE2:AE1000,"Unsatisfactory") -> 8
A7: Slit: Unsatisfactory | B7: =COUNTIFS('Patient Data'!AD2:AD1000,"Unsatisfactory",'Patient Data'!AE2:AE1000,"Satisfactory") -> 5 | C7: =COUNTIFS('Patient Data'!AD2:AD1000,"Unsatisfactory",'Patient Data'!AE2:AE1000,"Unsatisfactory") -> 4
A9: Discordant pairs (b, c): | B9: =C6 -> 8 | C9: =B7 -> 5
A10: McNemar chi-square (continuity corrected): | B10: =IFERROR((ABS(C6-B7)-1)^2/(C6+B7),"n/a") -> 0.30769231
A11: p-value: | B11: =IFERROR(CHIDIST(B10,1),"n/a") -> 0.57909974
A12: p < 0.05 suggests the two devices disagree on examination outcome more often than expected by chance. Needs at least a few discordant pairs (b or c > 0) to be meaningful.
A14: 2. Cohen's Kappa — Agreement on Examination Outcome
A15: Measures how much the two devices agree, beyond what chance agreement alone would give.
A16: Total paired observations (n): | B16: =B6+C6+B7+C7 -> 27
A17: Observed agreement (Po): | B17: =IFERROR((B6+C7)/B16,"n/a") -> 0.51851852
A18: Expected agreement (Pe): | B18: =IFERROR(((B6+C6)*(B6+B7)+(B7+C7)*(C6+C7))/(B16^2),"n/a") -> 0.51851852
A19: Cohen's Kappa: | B19: =IFERROR((B17-B18)/(1-B18),"n/a") -> 0
A20: Rule of thumb: <0 poor, 0.01-0.20 slight, 0.21-0.40 fair, 0.41-0.60 moderate, 0.61-0.80 substantial, 0.81-1.00 almost perfect agreement.
A22: 3. Paired t-test — IOP (Slit Lamp vs Smart Camera)
A23: Mean difference (Slit − Camera): | B23: =IFERROR(AVERAGE('Patient Data'!M2:M1000)-AVERAGE('Patient Data'!N2:N1000),"") -> -0.29215686
A24: p-value (2-tailed, paired): | B24: =IFERROR(TTEST('Patient Data'!M2:M1000,'Patient Data'!N2:N1000,2,1),"") -> 0.14741641
A25: Same test also appears on the 'Clinical Analysis' sheet for IOP, SPH, CYL and Axis together.
A27: 4. Wilcoxon Signed-Rank Test & Bland-Altman
A28: Excel has no built-in Wilcoxon signed-rank or Bland-Altman formula. If your data is not normally distributed and you need the Wilcoxon test, or a full Bland-Altman plot, export the 'Patient Data' sheet as CSV and run it through R, SPSS, or a statistics tool of your choice.

Sheet Data Quality
A1: DATA QUALITY REPORT
A3: Check | B3: Count
A4: Total records | B4: =COUNTA('Patient Data'!A2:A1000) -> 51
A5: Rows sharing a duplicate Study ID | B5: =SUMPRODUCT((COUNTIF('Patient Data'!A2:A1000,'Patient Data'!A2:A1000)>1)*('Patient Data'!A2:A1000<>"")) -> 0
A6: Missing Study ID (row has a name but no ID) | B6: =COUNTIFS('Patient Data'!B2:B1000,"<>",'Patient Data'!A2:A1000,"") -> 0
A7: Missing Age (row has an ID but no age) | B7: =COUNTIFS('Patient Data'!A2:A1000,"<>",'Patient Data'!C2:C1000,"") -> 0
A8: Missing Diagnosis (row has an ID but no diagnosis) | B8: =COUNTIFS('Patient Data'!A2:A1000,"<>",'Patient Data'!AB2:AB1000,"") -> 0
A9: Missing/unrecorded Slit Lamp examination | B9: =COUNTIFS('Patient Data'!A2:A1000,"<>",'Patient Data'!AD2:AD1000,"Not recorded")+COUNTIFS('Patient Data'!A2:A1000,"<>",'Patient Data'!AD2:AD1000,"") -> 15
A10: Missing/unrecorded Smart Camera examination | B10: =COUNTIFS('Patient Data'!A2:A1000,"<>",'Patient Data'!AE2:AE1000,"Not recorded")+COUNTIFS('Patient Data'!A2:A1000,"<>",'Patient Data'!AE2:AE1000,"") -> 12
A12: Recommendation: resolve duplicate Study IDs and important missing values before running the statistical tests, so the paired comparisons stay accurate.
